<?xml version="1.0" ?>
<!-- =================================================================================== -->
<!-- |    This document was autogenerated by xacro from robots/tiago_full.urdf.xacro   | -->
<!-- |    EDITING THIS FILE BY HAND IS NOT RECOMMENDED                                 | -->
<!-- =================================================================================== -->
<!--
  Copyright (c) 2011, PAL Robotics, S.L.
  All rights reserved.

  This work is licensed under the Creative Commons Attribution-NonCommercial-NoDerivs 3.0 Unported License.
  To view a copy of this license, visit http://creativecommons.org/licenses/by-nc-nd/3.0/ or send a letter to
  Creative Commons, 444 Castro Street, Suite 900, Mountain View, California, 94041, USA.
-->
<robot name="tiago" xmlns:controller="http://playerstage.sourceforge.net/gazebo/xmlschema/#controller" xmlns:interface="http://playerstage.sourceforge.net/gazebo/xmlschema/#interface" xmlns:sensor="http://playerstage.sourceforge.net/gazebo/xmlschema/#sensor" xmlns:xacro="http://ros.org/wiki/xacro">
  <!-- The following included files set up definitions of parts of the robot body -->
  <!-- Base -->
  <!-- Torso -->
  <!-- Generic simulator_gazebo plugins -->
  <gazebo>
    <plugin filename="libgazebo_ros_control.so" name="gazebo_ros_control">
      <ns/>
      <robotSimType>reemc_hardware_gazebo/ReemcHardwareGazebo</robotSimType>
      <robotNamespace/>
      <controlPeriod>0.001</controlPeriod>
    </plugin>
    <plugin filename="libgazebo_ros_p3d.so" name="gazebo_ros_p3d">
      <bodyName>base_link</bodyName>
      <topicName>ground_truth_odom</topicName>
      <alwaysOn>true</alwaysOn>
      <updateRate>100.0</updateRate>
    </plugin>
  </gazebo>
  <gazebo>
    <plugin filename="libgazebo_ros_force.so" name="gazebo_ros_force">
      <bodyName>base_link</bodyName>
      <topicName>base_link_wrench</topicName>
    </plugin>
  </gazebo>
  <gazebo reference="imu_link">
    <!-- this is expected to be reparented to pelvis with appropriate offset
         when imu_link is reduced by fixed joint reduction -->
    <!-- todo: this is working with gazebo 1.4, need to write a unit test -->
    <sensor name="imu_sensor" type="imu">
      <always_on>1</always_on>
      <update_rate>1000.0</update_rate>
      <imu>
        <noise>
          <type>gaussian</type>
          <!-- Noise parameters from Boston Dynamics
               (http://gazebosim.org/wiki/Sensor_noise):
                 rates (rad/s): mean=0, stddev=2e-4
                 accels (m/s/s): mean=0, stddev=1.7e-2
                 rate bias (rad/s): 5e-6 - 1e-5
                 accel bias (m/s/s): 1e-1
               Experimentally, simulation provide rates with noise of
               about 1e-3 rad/s and accels with noise of about 1e-1 m/s/s.
               So we don't expect to see the noise unless number of inner iterations
               are increased.

               We will add bias.  In this model, bias is sampled once for rates
               and once for accels at startup; the sign (negative or positive)
               of each bias is then switched with equal probability.  Thereafter,
               the biases are fixed additive offsets.  We choose
               bias means and stddevs to produce biases close to the provided
               data. -->
          <rate>
            <mean>0.0</mean>
            <stddev>2e-4</stddev>
            <bias_mean>0.0000075</bias_mean>
            <bias_stddev>0.0000008</bias_stddev>
          </rate>
          <accel>
            <mean>0.0</mean>
            <stddev>1.7e-2</stddev>
            <bias_mean>0.1</bias_mean>
            <bias_stddev>0.001</bias_stddev>
          </accel>
        </noise>
      </imu>
    </sensor>
  </gazebo>
  <gazebo reference="r_foot">
    <mu1>0.9</mu1>
    <mu2>0.9</mu2>
    <fdir1>1 0 0</fdir1>
    <maxVel>1.0</maxVel>
    <minDepth>0.003</minDepth>
  </gazebo>
  <gazebo reference="l_foot">
    <mu1>0.9</mu1>
    <mu2>0.9</mu2>
    <fdir1>1 0 0</fdir1>
    <maxVel>1.0</maxVel>
    <minDepth>0.003</minDepth>
  </gazebo>
  <!-- Materials for visualization -->
  <material name="Blue">
    <color rgba="0.0 0.0 0.8 1.0"/>
  </material>
  <material name="Green">
    <color rgba="0.0 0.8 0.0 1.0"/>
  </material>
  <material name="Grey">
    <color rgba="0.7 0.7 0.7 1.0"/>
  </material>
  <material name="LightGrey">
    <color rgba="0.9 0.9 0.9 1.0"/>
  </material>
  <material name="DarkGrey">
    <color rgba="0.2 0.2 0.2 1.0"/>
  </material>
  <material name="Red">
    <color rgba="0.8 0.0 0.0 1.0"/>
  </material>
  <material name="White">
    <color rgba="1.0 1.0 1.0 1.0"/>
  </material>
  <!-- Now we can start using the macros included above to define the actual robot -->
  <link name="base_link">
    <inertial>
      <origin rpy="0 0 0" xyz="0.0123 0.0071 0.064"/>
      <mass value="7.95534"/>
      <inertia ixx="0.19540233297" ixy="-0.00188862789" ixz="-0.00370655921" iyy="0.23325457568" iyz="0.00387528692" izz="0.3312456162"/>
    </inertial>
    <visual>
      <origin rpy="0 0 0" xyz="0 0 0"/>
      <geometry>
        <!--cylinder radius="${base_radius}" length="${base_length}"/-->
        <mesh filename="package://ant_description/meshes/base/base.stl"/>
        <!--mesh filename="package://ant_description/meshes/base/base.dae" /-->
      </geometry>
      <material name="DarkGrey"/>
    </visual>
    <collision>
      <origin rpy="0 0 0" xyz="0 0 0"/>
      <geometry>
        <cylinder length="0.04" radius="0.18504"/>
        <!-- @todo base_collision.stl still the same as base.stl -->
        <!--mesh filename="package://ant_description/meshes/base/base_collision.stl" /-->
      </geometry>
      <material name="DarkGrey"/>
    </collision>
  </link>
  <link name="base_footprint"/>
  <joint name="base_footprint_joint" type="fixed">
    <origin rpy="0 0 0" xyz="0 0 0.1"/>
    <child link="base_link"/>
    <parent link="base_footprint"/>
  </joint>
  <link name="base_laser_link" type="laser">
    <inertial>
      <origin rpy="0 0 0" xyz="0 0 -0.04225"/>
      <mass value="0.160"/>
      <inertia ixx="0.00008631543" ixy="-0.00000088815" ixz="-0.00000094079" iyy="0.00008461544" iyz="0.00000139389" izz="0.00005947238"/>
    </inertial>
    <visual>
      <origin rpy="0 0 0" xyz="0 0 0"/>
      <geometry>
        <mesh filename="package://ant_description/meshes/sensors/urg-04lx-ug01.stl"/>
      </geometry>
      <material name="DarkGrey"/>
    </visual>
  </link>
  <joint name="base_laser_joint" type="fixed">
    <axis xyz="0 1 0"/>
    <origin rpy="0 0 0" xyz="0.185 0.0 0.05275"/>
    <parent link="base_link"/>
    <child link="base_laser_link"/>
    <dynamics damping="1" friction="1.0"/>
    <limit effort="60" lower="0" upper="0" velocity="20"/>
  </joint>
  <gazebo reference="base_laser_link">
    <sensor name="base_laser" type="ray">
      <pose>0 0 0 0 0 0</pose>
      <update_rate>10</update_rate>
      <visualize>true</visualize>
      <ray>
        <scan>
          <horizontal>
            <!-- 683 steps in 240deg fov -->
            <samples>512.249999998</samples>
            <resolution>1</resolution>
            <!-- not the sensor resolution; just 1 -->
            <min_angle>-1.57079632679</min_angle>
            <max_angle>1.57079632679</max_angle>
          </horizontal>
        </scan>
        <range>
          <min>0.02</min>
          <max>5.6</max>
          <resolution>0.001</resolution>
        </range>
      </ray>
      <plugin filename="libgazebo_ros_laser.so" name="gazebo_ros_hokuyo_laser">
        <gaussianNoise>0.03</gaussianNoise>
        <alwaysOn>true</alwaysOn>
        <updateRate>10</updateRate>
        <topicName>scan</topicName>
        <frameName>base_laser_link</frameName>
      </plugin>
    </sensor>
  </gazebo>
  <link name="base_inclinometer_link">
    <inertial>
      <mass value="0.01"/>
      <origin xyz="0 0 0"/>
      <inertia ixx="0.000001" ixy="0" ixz="0" iyy="0.000001" iyz="0" izz="0.000001"/>
    </inertial>
    <!--visual>
        <origin rpy="0 0 0" xyz="0 0 0"/>
        <geometry>
          <box size="0.01 0.01 0.01"/>
        </geometry>
      </visual-->
  </link>
  <joint name="base_inclinometer_joint" type="fixed">
    <parent link="base_link"/>
    <child link="base_inclinometer_link"/>
    <origin rpy="0 0 0" xyz="0 0 0.02"/>
  </joint>
  <gazebo reference="base_inclinometer_link">
    <sensor name="base_inclinometer_sensor" type="imu">
      <always_on>1</always_on>
      <update_rate>100.0</update_rate>
      <imu>
        <noise>
          <type>gaussian</type>
          <rate>
            <mean>0.0</mean>
            <stddev>2e-4</stddev>
            <bias_mean>0.0000075</bias_mean>
            <bias_stddev>0.0000008</bias_stddev>
          </rate>
          <accel>
            <mean>0.0</mean>
            <stddev>1.7e-2</stddev>
            <bias_mean>0.1</bias_mean>
            <bias_stddev>0.001</bias_stddev>
          </accel>
        </noise>
      </imu>
    </sensor>
  </gazebo>
  <link name="wheel_right_link">
    <inertial>
      <origin rpy="0 0 0" xyz="0 0 -0.0016"/>
      <mass value="3.33926"/>
      <inertia ixx="0.00668369447" ixy="0.00000007414" ixz="0.00000024433" iyy="0.00668332554" iyz="-0.00000005662" izz="0.01088090651"/>
    </inertial>
    <visual>
      <origin rpy="0 0 0" xyz="0 0 0"/>
      <geometry>
        <cylinder length="0.044" radius="0.1"/>
      </geometry>
      <material name="LightGrey"/>
    </visual>
    <collision>
      <origin rpy="0 0 0" xyz="0 0 0"/>
      <geometry>
        <cylinder length="0.044" radius="0.1"/>
      </geometry>
      <surface>
        <friction>
          <ode>
            <mu> 0.01</mu>
            <mu2>0.01</mu2>
          </ode>
        </friction>
      </surface>
    </collision>
  </link>
  <joint name="wheel_right_joint" type="continuous">
    <parent link="base_link"/>
    <child link="wheel_right_link"/>
    <origin rpy="-1.57079632679 0 0" xyz="0 -0.21704 0"/>
    <axis xyz="0 0 1"/>
    <limit effort="6.0" velocity="10.0"/>
  </joint>
  <transmission name="wheel_right_trans">
    <type>transmission_interface/SimpleTransmission</type>
    <actuator name="wheel_right_motor">
      <mechanicalReduction>1.0</mechanicalReduction>
    </actuator>
    <joint name="wheel_right_joint">
      <hardwareInterface>hardware_interface/VelocityJointInterface</hardwareInterface>
    </joint>
  </transmission>
  <gazebo reference="wheel_right_link">
    <kp>100000000.0</kp>
    <kd>10000.0</kd>
    <mu1>1.0</mu1>
    <mu2>1.0</mu2>
    <minDepth>0.00</minDepth>
  </gazebo>
  <link name="wheel_left_link">
    <inertial>
      <origin rpy="0 0 0" xyz="0 0 -0.0016"/>
      <mass value="3.33926"/>
      <inertia ixx="0.00668369447" ixy="0.00000007414" ixz="0.00000024433" iyy="0.00668332554" iyz="-0.00000005662" izz="0.01088090651"/>
    </inertial>
    <visual>
      <origin rpy="0 0 0" xyz="0 0 0"/>
      <geometry>
        <cylinder length="0.044" radius="0.1"/>
      </geometry>
      <material name="LightGrey"/>
    </visual>
    <collision>
      <origin rpy="0 0 0" xyz="0 0 0"/>
      <geometry>
        <cylinder length="0.044" radius="0.1"/>
      </geometry>
      <surface>
        <friction>
          <ode>
            <mu> 0.01</mu>
            <mu2>0.01</mu2>
          </ode>
        </friction>
      </surface>
    </collision>
  </link>
  <joint name="wheel_left_joint" type="continuous">
    <parent link="base_link"/>
    <child link="wheel_left_link"/>
    <origin rpy="-1.57079632679 0 0" xyz="0 0.21704 0"/>
    <axis xyz="0 0 1"/>
    <limit effort="6.0" velocity="10.0"/>
  </joint>
  <transmission name="wheel_left_trans">
    <type>transmission_interface/SimpleTransmission</type>
    <actuator name="wheel_left_motor">
      <mechanicalReduction>1.0</mechanicalReduction>
    </actuator>
    <joint name="wheel_left_joint">
      <hardwareInterface>hardware_interface/VelocityJointInterface</hardwareInterface>
    </joint>
  </transmission>
  <gazebo reference="wheel_left_link">
    <kp>100000000.0</kp>
    <kd>10000.0</kd>
    <mu1>1.0</mu1>
    <mu2>1.0</mu2>
    <minDepth>0.00</minDepth>
  </gazebo>
  <link name="caster_front_right_1_link">
    <inertial>
      <origin rpy="0 0 0" xyz="-0.00653 -0.00008 -0.01177"/>
      <mass value="0.09556"/>
      <inertia ixx="0.00002195406" ixy="0.00000000009" ixz="0.00000370909" iyy="0.00001717745" iyz="-0.00000000032" izz="0.00002240463"/>
    </inertial>
    <visual>
      <origin rpy="0 0 0" xyz="0 0 0"/>
      <geometry>
        <!--box size="${radius} ${1.2 * width} ${radius}"/-->
        <mesh filename="package://ant_description/meshes/wheels/caster.stl"/>
      </geometry>
      <material name="Grey"/>
    </visual>
    <collision>
      <origin rpy="0 0 0" xyz="0 0 0"/>
      <geometry>
        <!--box size="${radius} ${1.2 * width} ${radius}"/-->
        <mesh filename="package://ant_description/meshes/wheels/caster.stl"/>
      </geometry>
    </collision>
  </link>
  <link name="caster_front_right_2_link">
    <inertial>
      <origin rpy="0 0 0" xyz="0 0 0"/>
      <mass value="0.02425"/>
      <inertia ixx="0.00000464376" ixy="0" ixz="0" iyy="0.00000464377" iyz="0" izz="0.00000802779"/>
    </inertial>
    <visual>
      <origin rpy="0 0 0" xyz="0 0 0"/>
      <geometry>
        <cylinder length="0.02" radius="0.025"/>
      </geometry>
      <material name="DarkGrey"/>
    </visual>
    <collision>
      <origin rpy="0 0 0" xyz="0 0 0"/>
      <geometry>
        <cylinder length="0.02" radius="0.025"/>
      </geometry>
      <surface>
        <friction>
          <ode>
            <mu> 0.01</mu>
            <mu2>0.01</mu2>
          </ode>
        </friction>
      </surface>
    </collision>
  </link>
  <joint name="caster_front_right_1_joint" type="continuous">
    <parent link="base_link"/>
    <child link="caster_front_right_1_link"/>
    <origin rpy="0 0 0" xyz="0.18367 -0.10181 -0.04252"/>
    <axis xyz="0 0 1"/>
  </joint>
  <joint name="caster_front_right_2_joint" type="continuous">
    <parent link="caster_front_right_1_link"/>
    <child link="caster_front_right_2_link"/>
    <origin rpy="-1.57079632679 0 0" xyz="-0.017 0.0003 -0.032"/>
    <axis xyz="0 0 1"/>
  </joint>
  <gazebo reference="caster_front_right_link">
    <kp>100000000.0</kp>
    <kd>10000.0</kd>
    <mu1>1.0</mu1>
    <mu2>1.0</mu2>
    <minDepth>0.00</minDepth>
  </gazebo>
  <link name="caster_front_left_1_link">
    <inertial>
      <origin rpy="0 0 0" xyz="-0.00653 -0.00008 -0.01177"/>
      <mass value="0.09556"/>
      <inertia ixx="0.00002195406" ixy="0.00000000009" ixz="0.00000370909" iyy="0.00001717745" iyz="-0.00000000032" izz="0.00002240463"/>
    </inertial>
    <visual>
      <origin rpy="0 0 0" xyz="0 0 0"/>
      <geometry>
        <!--box size="${radius} ${1.2 * width} ${radius}"/-->
        <mesh filename="package://ant_description/meshes/wheels/caster.stl"/>
      </geometry>
      <material name="Grey"/>
    </visual>
    <collision>
      <origin rpy="0 0 0" xyz="0 0 0"/>
      <geometry>
        <!--box size="${radius} ${1.2 * width} ${radius}"/-->
        <mesh filename="package://ant_description/meshes/wheels/caster.stl"/>
      </geometry>
    </collision>
  </link>
  <link name="caster_front_left_2_link">
    <inertial>
      <origin rpy="0 0 0" xyz="0 0 0"/>
      <mass value="0.02425"/>
      <inertia ixx="0.00000464376" ixy="0" ixz="0" iyy="0.00000464377" iyz="0" izz="0.00000802779"/>
    </inertial>
    <visual>
      <origin rpy="0 0 0" xyz="0 0 0"/>
      <geometry>
        <cylinder length="0.02" radius="0.025"/>
      </geometry>
      <material name="DarkGrey"/>
    </visual>
    <collision>
      <origin rpy="0 0 0" xyz="0 0 0"/>
      <geometry>
        <cylinder length="0.02" radius="0.025"/>
      </geometry>
      <surface>
        <friction>
          <ode>
            <mu> 0.01</mu>
            <mu2>0.01</mu2>
          </ode>
        </friction>
      </surface>
    </collision>
  </link>
  <joint name="caster_front_left_1_joint" type="continuous">
    <parent link="base_link"/>
    <child link="caster_front_left_1_link"/>
    <origin rpy="0 0 0" xyz="0.18367 0.10181 -0.04252"/>
    <axis xyz="0 0 1"/>
  </joint>
  <joint name="caster_front_left_2_joint" type="continuous">
    <parent link="caster_front_left_1_link"/>
    <child link="caster_front_left_2_link"/>
    <origin rpy="-1.57079632679 0 0" xyz="-0.017 0.0003 -0.032"/>
    <axis xyz="0 0 1"/>
  </joint>
  <gazebo reference="caster_front_left_link">
    <kp>100000000.0</kp>
    <kd>10000.0</kd>
    <mu1>1.0</mu1>
    <mu2>1.0</mu2>
    <minDepth>0.00</minDepth>
  </gazebo>
  <link name="caster_back_right_1_link">
    <inertial>
      <origin rpy="0 0 0" xyz="-0.00653 -0.00008 -0.01177"/>
      <mass value="0.09556"/>
      <inertia ixx="0.00002195406" ixy="0.00000000009" ixz="0.00000370909" iyy="0.00001717745" iyz="-0.00000000032" izz="0.00002240463"/>
    </inertial>
    <visual>
      <origin rpy="0 0 0" xyz="0 0 0"/>
      <geometry>
        <!--box size="${radius} ${1.2 * width} ${radius}"/-->
        <mesh filename="package://ant_description/meshes/wheels/caster.stl"/>
      </geometry>
      <material name="Grey"/>
    </visual>
    <collision>
      <origin rpy="0 0 0" xyz="0 0 0"/>
      <geometry>
        <!--box size="${radius} ${1.2 * width} ${radius}"/-->
        <mesh filename="package://ant_description/meshes/wheels/caster.stl"/>
      </geometry>
    </collision>
  </link>
  <link name="caster_back_right_2_link">
    <inertial>
      <origin rpy="0 0 0" xyz="0 0 0"/>
      <mass value="0.02425"/>
      <inertia ixx="0.00000464376" ixy="0" ixz="0" iyy="0.00000464377" iyz="0" izz="0.00000802779"/>
    </inertial>
    <visual>
      <origin rpy="0 0 0" xyz="0 0 0"/>
      <geometry>
        <cylinder length="0.02" radius="0.025"/>
      </geometry>
      <material name="DarkGrey"/>
    </visual>
    <collision>
      <origin rpy="0 0 0" xyz="0 0 0"/>
      <geometry>
        <cylinder length="0.02" radius="0.025"/>
      </geometry>
      <surface>
        <friction>
          <ode>
            <mu> 0.01</mu>
            <mu2>0.01</mu2>
          </ode>
        </friction>
      </surface>
    </collision>
  </link>
  <joint name="caster_back_right_1_joint" type="continuous">
    <parent link="base_link"/>
    <child link="caster_back_right_1_link"/>
    <origin rpy="0 0 0" xyz="-0.18367 -0.10181 -0.04252"/>
    <axis xyz="0 0 1"/>
  </joint>
  <joint name="caster_back_right_2_joint" type="continuous">
    <parent link="caster_back_right_1_link"/>
    <child link="caster_back_right_2_link"/>
    <origin rpy="-1.57079632679 0 0" xyz="-0.017 0.0003 -0.032"/>
    <axis xyz="0 0 1"/>
  </joint>
  <gazebo reference="caster_back_right_link">
    <kp>100000000.0</kp>
    <kd>10000.0</kd>
    <mu1>1.0</mu1>
    <mu2>1.0</mu2>
    <minDepth>0.00</minDepth>
  </gazebo>
  <link name="caster_back_left_1_link">
    <inertial>
      <origin rpy="0 0 0" xyz="-0.00653 -0.00008 -0.01177"/>
      <mass value="0.09556"/>
      <inertia ixx="0.00002195406" ixy="0.00000000009" ixz="0.00000370909" iyy="0.00001717745" iyz="-0.00000000032" izz="0.00002240463"/>
    </inertial>
    <visual>
      <origin rpy="0 0 0" xyz="0 0 0"/>
      <geometry>
        <!--box size="${radius} ${1.2 * width} ${radius}"/-->
        <mesh filename="package://ant_description/meshes/wheels/caster.stl"/>
      </geometry>
      <material name="Grey"/>
    </visual>
    <collision>
      <origin rpy="0 0 0" xyz="0 0 0"/>
      <geometry>
        <!--box size="${radius} ${1.2 * width} ${radius}"/-->
        <mesh filename="package://ant_description/meshes/wheels/caster.stl"/>
      </geometry>
    </collision>
  </link>
  <link name="caster_back_left_2_link">
    <inertial>
      <origin rpy="0 0 0" xyz="0 0 0"/>
      <mass value="0.02425"/>
      <inertia ixx="0.00000464376" ixy="0" ixz="0" iyy="0.00000464377" iyz="0" izz="0.00000802779"/>
    </inertial>
    <visual>
      <origin rpy="0 0 0" xyz="0 0 0"/>
      <geometry>
        <cylinder length="0.02" radius="0.025"/>
      </geometry>
      <material name="DarkGrey"/>
    </visual>
    <collision>
      <origin rpy="0 0 0" xyz="0 0 0"/>
      <geometry>
        <cylinder length="0.02" radius="0.025"/>
      </geometry>
      <surface>
        <friction>
          <ode>
            <mu> 0.01</mu>
            <mu2>0.01</mu2>
          </ode>
        </friction>
      </surface>
    </collision>
  </link>
  <joint name="caster_back_left_1_joint" type="continuous">
    <parent link="base_link"/>
    <child link="caster_back_left_1_link"/>
    <origin rpy="0 0 0" xyz="-0.18367 0.10181 -0.04252"/>
    <axis xyz="0 0 1"/>
  </joint>
  <joint name="caster_back_left_2_joint" type="continuous">
    <parent link="caster_back_left_1_link"/>
    <child link="caster_back_left_2_link"/>
    <origin rpy="-1.57079632679 0 0" xyz="-0.017 0.0003 -0.032"/>
    <axis xyz="0 0 1"/>
  </joint>
  <gazebo reference="caster_back_left_link">
    <kp>100000000.0</kp>
    <kd>10000.0</kd>
    <mu1>1.0</mu1>
    <mu2>1.0</mu2>
    <minDepth>0.00</minDepth>
  </gazebo>
  <link name="torso_fixed_link">
    <inertial>
      <origin rpy="0 0 0" xyz="0.053 0.55187 -0.00188"/>
      <mass value="7.19400"/>
      <inertia ixx="0.16941095831" ixy="-0.00114443001" ixz="0.00090167218" iyy="0.15113888533" iyz="-0.00744737659" izz="0.04165307088"/>
    </inertial>
    <collision>
      <origin rpy="0 0 0" xyz="0.13 0.45 0"/>
      <geometry>
        <box size="0.20 0.40 0.32"/>
      </geometry>
    </collision>
  </link>
  <joint name="torso_fixed_joint" type="fixed">
    <origin rpy="0 0 0" xyz="-0.053 0 0"/>
    <parent link="base_link"/>
    <child link="torso_lift_link"/>
    <axis xyz="0 0 0"/>
  </joint>
  <link name="torso_lift_link">
    <inertial>
      <origin rpy="0 0 0" xyz="-0.060142360276412 0.00304133533168627 0.343272867034157"/>
      <mass value="10.81628746254819"/>
      <inertia ixx="0.0641960264706125" ixy="0.001128617953499" ixz="0.00203364821006436" iyy="0.061658561971383" iyz="-3.14401755382909E-05" izz="0.0376084656328484"/>
    </inertial>
    <collision>
      <origin rpy="0 0 0" xyz="0 -.02 0"/>
      <geometry>
        <box size="0.20 0.40 0.32"/>
      </geometry>
    </collision>
  </link>
  <joint name="torso_lift_joint" type="prismatic">
    <origin rpy="0 0 0" xyz="0.0 0 0.26428"/>
    <parent link="torso_fixed_link"/>
    <child link="torso_lift_link"/>
    <axis xyz="0 0 1"/>
    <limit effort="450" lower="0.0" upper="0.3556" velocity="0.1"/>
    <calibration rising="0.0"/>
    <dynamics damping="1000"/>
  </joint>
  <!--<xacro:reem_head  name="head"  parent="torso_2_link"/>
  <xacro:reem_arm name="arm" parent="torso_2_link" side="right" reflect="1.0"  /> -->
</robot>

