<?xml version="1.0"?>
<!--

  Copyright (c) 2011-2012, PAL Robotics, S.L.
  All rights reserved.

  This work is licensed under the Creative Commons Attribution-NonCommercial-NoDerivs 3.0 Unported License.
  To view a copy of this license, visit http://creativecommons.org/licenses/by-nc-nd/3.0/ or send a letter to
  Creative Commons, 444 Castro Street, Suite 900, Mountain View, California, 94041, USA.
-->
<robot xmlns:xacro="http://ros.org/wiki/xacro">

  <!--File includes-->
  <xacro:include filename="$(find reemc_description)/urdf/deg_to_rad.xacro" />
  <xacro:include filename="$(find reemc_description)/urdf/arm/wrist.transmission.xacro" />

  <!--Constant parameters-->
  <xacro:property name="wrist_friction"       value="1.0" />
  <xacro:property name="wrist_damping"        value="1.0" />
  <xacro:property name="wrist_1_max_vel"      value="1.95" />
  <xacro:property name="wrist_2_max_vel"      value="1.76" />
  <xacro:property name="wrist_3_max_vel"      value="1.76" />
  <xacro:property name="wrist_1_max_effort"   value="3" />
  <xacro:property name="wrist_2_max_effort"   value="6.6" />
  <xacro:property name="wrist_3_max_effort"   value="6.6" />
  <xacro:property name="wrist_eps"          value="0.02" />

  <!-- TODO: Update dynamic models -->

  <xacro:macro name="reem_wrist" params="name parent side reflect">

    <!--************************-->
    <!--        WRIST           -->
    <!--************************-->
    <link name="${name}_${side}_5_link">
      <inertial>
        <origin xyz="-0.00044 0.00012 ${reflect * 0.07445}" rpy="0 0 0"/>
        <mass value="1.21524" />
        <!-- <inertia ixx="0"  ixy="0"  ixz="0" iyy="0" iyz="0" izz="0" /> -->
        <!-- NOTE: Assuming cylinder centered at CoM with r=0.05, h=0.1 with axis parallel to z coordinate -->
<!--         <inertia ixx="0.0027096"  ixy="0"  ixz="0" iyy="0.0027096" iyz="0" izz="0.0023225" /> -->

      <inertia ixx="0.00193499547"  ixy="-0.00000027528"  ixz="-0.00001268153" iyy="0.00177767506" iyz="-0.00000466638" izz="0.00057101196" />
      </inertial>
      <visual>
        <origin xyz="0 0 0" rpy="0 0 0" />
        <geometry>
          <mesh filename="package://reemc_description/meshes/arm/arm_5.dae" scale="1 1 ${-1*reflect}"/>
        </geometry>
        <material name="LightGrey" />
      </visual>
      <collision>
        <origin xyz="0 0 0" rpy="0 0 0" />
        <geometry>
          <mesh filename="package://reemc_description/meshes/arm/arm_5_collision.stl" scale="1 1 ${-1*reflect}"/>
        </geometry>
      </collision>
    </link>

    <joint name="${name}_${side}_5_joint" type="revolute">
      <parent link="${parent}" />
      <child link="${name}_${side}_5_link" />
      <origin xyz="-0.088 0.02 0" rpy="0 ${-90.0 * reflect * deg_to_rad} 0" />
      <axis xyz="0 0 1" />
      <limit lower="${-120.0 * deg_to_rad}" upper="${120.0 * deg_to_rad}" effort="${wrist_1_max_effort}" velocity="${wrist_1_max_vel}" /> <!--TODO: Check effort value!-->
      <dynamics friction="${wrist_friction}" damping="${wrist_damping}"/>

      <safety_controller k_position="20"
                         k_velocity="20"
                         soft_lower_limit="${-120.0 * deg_to_rad + wrist_eps}"
                         soft_upper_limit="${ 120.0 * deg_to_rad - wrist_eps}" />
    </joint>

    <link name="${name}_${side}_6_link">
      <inertial>
        <origin xyz="-0.00005 -0.00252 ${reflect * 0.00007}" rpy="0 0 0"/>
        <mass value="0.41597" />
        <!-- <inertia ixx="0"  ixy="0"  ixz="0" iyy="0" iyz="0" izz="0" /> -->
        <!-- NOTE: Assuming cylinder centered at CoM with r=0.02, h=0.08 with axis parallel to z coordinate -->
<!--         <inertia ixx="0.0001615"  ixy="0"  ixz="0" iyy="0.0001615" iyz="0" izz="0.000051" /> -->
         <inertia ixx="0.00020339659"  ixy="-0.00000071703"  ixz="-0.00000006654" iyy="0.00015240261" iyz="0.00000014315" izz="0.0001671881" />
      </inertial>
      <visual>
        <origin xyz="0 0 0" rpy="0 0 0" />
        <geometry>
          <mesh filename="package://reemc_description/meshes/arm/arm_6.dae" scale="1 1 ${-1*reflect}"/>
        </geometry>
        <material name="LightGrey" />
      </visual>
      <collision>
        <origin xyz="0 0 0" rpy="0 0 0" />
        <geometry>
          <cylinder radius="0.04" length="0.0385"/>
        </geometry>
      </collision>
    </link>

    <joint name="${name}_${side}_6_joint" type="revolute">
      <parent link="${name}_${side}_5_link" />
      <child link="${name}_${side}_6_link" />
      <origin xyz="0 0 ${0.15 * reflect}" rpy="${-90.0 * reflect * deg_to_rad} 0 0" />
      <axis xyz="0 0 1" />
      <limit lower="${-90.0 * deg_to_rad}" upper="${90.0 * deg_to_rad}" effort="${wrist_2_max_effort}" velocity="${wrist_2_max_vel}" />
      <dynamics friction="${wrist_friction}" damping="${wrist_damping}"/>

      <safety_controller k_position="20"
                         k_velocity="20"
                         soft_lower_limit="${-90.0 * deg_to_rad + wrist_eps}"
                         soft_upper_limit="${ 90.0 * deg_to_rad - wrist_eps}" />
    </joint>

    <link name="${name}_${side}_7_link">
      <inertial>
        <!--TODO: Verify these inertial parameters-->
        <origin xyz="-0.00004 0 ${reflect * -0.02887}" rpy="0 0 0"/>
        <mass value="0.06697" />
       <!-- <inertia ixx="0"  ixy="0"  ixz="0" iyy="0" iyz="0" izz="0" /> -->
        <!-- NOTE: Assuming point mass -->
<!--         <inertia ixx="0"  ixy="0"  ixz="0" iyy="0" iyz="0" izz="0" /> -->
         <inertia ixx="0.0000123718"  ixy="0.00000000002"  ixz="0.00000002403" iyy="0.00001242132" iyz="0.00000000001" izz="0.0000059514" />
      </inertial>
      <visual>
        <origin xyz="0 0 ${0.046 * reflect}" rpy="0 0 0" />
        <geometry>
          <cylinder radius="0.02" length="0.005"/>
        </geometry>
        <material name="DarkGrey" />
      </visual>
      <collision>
        <origin xyz="0 0 ${0.046 * 0.75 * reflect}" rpy="0 0 0" />
        <geometry>
          <cylinder radius="0.02" length="0.023"/>
        </geometry>
      </collision>
    </link>

    <joint name="${name}_${side}_7_joint" type="revolute">
      <parent link="${name}_${side}_6_link" />
      <child link="${name}_${side}_7_link" />
      <origin xyz="0 0 0" rpy="${90.0 * reflect * deg_to_rad} 0 0" />
      <axis xyz="0 0 1" />
      <limit lower="${-120.0 * deg_to_rad}" upper="${120.0 * deg_to_rad}" effort="${wrist_3_max_effort}" velocity="${wrist_3_max_vel}" />
      <dynamics friction="${wrist_friction}" damping="${wrist_damping}"/>

      <safety_controller k_position="20"
                         k_velocity="20"
                         soft_lower_limit="${-120.0 * deg_to_rad + wrist_eps}"
                         soft_upper_limit="${ 120.0 * deg_to_rad - wrist_eps}" />
    </joint>

    <gazebo reference="${name}_${side}_5_link">
      <mu1>0.9</mu1>
      <mu2>0.9</mu2>
    </gazebo>
    <gazebo reference="${name}_${side}_6_link">
      <mu1>0.9</mu1>
      <mu2>0.9</mu2>
    </gazebo>
    <gazebo reference="${name}_${side}_7_link">
      <mu1>0.9</mu1>
      <mu2>0.9</mu2>
    </gazebo>

    <gazebo reference="${name}_${side}_5_joint">
        <implicitSpringDamper>1</implicitSpringDamper>
    </gazebo>
    <gazebo reference="${name}_${side}_6_joint">
        <implicitSpringDamper>1</implicitSpringDamper>
    </gazebo>
    <gazebo reference="${name}_${side}_7_joint">
        <implicitSpringDamper>1</implicitSpringDamper>
    </gazebo>

    <!-- extensions -->
    <xacro:reem_wrist_simple_transmission name="${name}" side="${side}" number="5" reduction="1.0" />
    <xacro:reem_wrist_differential_transmission name="${name}" side="${side}" number_1="6" number_2="7"
                                                act_reduction_1="-1.0" act_reduction_2="1.0"
                                                jnt_reduction_1="-1.0" jnt_reduction_2="${-reflect}" />

  </xacro:macro>

</robot>
