<?xml version="1.0"?>
<!--

  Copyright (c) 2011-2012, PAL Robotics, S.L.
  All rights reserved.

  This work is licensed under the Creative Commons Attribution-NonCommercial-NoDerivs 3.0 Unported License.
  To view a copy of this license, visit http://creativecommons.org/licenses/by-nc-nd/3.0/ or send a letter to
  Creative Commons, 444 Castro Street, Suite 900, Mountain View, California, 94041, USA.
-->
<robot xmlns:xacro="http://ros.org/wiki/xacro">

  <!--File includes-->
  <xacro:include filename="$(find tiago_description)/urdf/deg_to_rad.xacro" />
  <xacro:include filename="$(find tiago_description)/urdf/head/head.transmission.xacro" />
  <xacro:include filename="$(find tiago_description)/urdf/sensors/xtion_pro_live.urdf.xacro" />

  <!--Constant parameters-->
  <xacro:property name="head_friction" value="1.0" />
  <xacro:property name="head_damping"  value="0.5" />
  <xacro:property name="head_max_vel"  value="3.0" />
  <xacro:property name="head_eps"      value="0.02" />

  <!--************************-->
  <!--     HEAD_1 (PAN)       -->
  <!--************************-->
  <xacro:macro name="head_1" params="name parent">
    <link name="${name}_link">
      <inertial>
        <origin xyz="0.01819	0.00248	-0.00517" rpy="0 0 0" />
        <mass value="1.11967" />
        <inertia ixx="0.00111370229"  ixy="0.00003992198"  ixz="-0.00012464155" iyy="0.00111361487" iyz="0.00001943162" izz="0.00114794061" />
      </inertial>
      <visual>
        <origin rpy="0 0 0" xyz="0.03 0 0"/>
        <geometry>
          <box size="0.06 0.04 0.04"/>
        </geometry>
        <material name="Grey" />
      </visual>
      <collision>
        <origin xyz="0.03 0 0" rpy="0 0 0" />
        <geometry>
          <box size="0.06 0.04 0.04"/>
        </geometry>
        <material name="Grey" />
      </collision>
    </link>

    <joint name="${name}_joint" type="revolute">
      <parent link="${parent}"/>
      <child link="${name}_link"/>
      <origin xyz="0 0 0.04" rpy="${0.0 * deg_to_rad} 0 0" />
      <axis xyz="0 0 1" />
      <limit lower="${-75.0 * deg_to_rad}" upper="${75.0 * deg_to_rad}" effort="3.4" velocity="${head_max_vel}" />
      <dynamics damping="${head_damping}" friction="${head_friction}"/>

      <safety_controller k_position="20"
                         k_velocity="20"
                         soft_lower_limit="${-75.0 * deg_to_rad + head_eps}"
                         soft_upper_limit="${ 75.0 * deg_to_rad - head_eps}" />
    </joint>

    <gazebo reference="${name}_link">
      <mu1>0.9</mu1>
      <mu2>0.9</mu2>
    </gazebo>

    <gazebo reference="${name}_joint">
       <implicitSpringDamper>1</implicitSpringDamper>
    </gazebo>


    <!-- extensions -->
    <xacro:head_transmission name="${name}" reduction="1" />

  </xacro:macro>

  <!--************************-->
  <!--      HEAD_2 (TILT)     -->
  <!--************************-->
  <xacro:macro name="head_2" params="name parent">
    <link name="${name}_link">
      <inertial>
        <origin xyz="0.01183 -0.08098 0.00104" rpy="0 0 0" />
        <mass value="1.63134" />
        <inertia ixx="0.00640199093"  ixy="0.00012197067"  ixz="-0.00000897011" iyy="0.00676228591" iyz="-0.0000552329" izz="0.00614192438" />
      </inertial>
      <visual>
        <origin xyz="-0.035 0 0" rpy="0 0 0"/>
        <geometry>
          <box size="0.035 0.035 0.05"/>
        </geometry>
        <material name="DarkGrey" />
      </visual>
      <collision>
        <origin xyz="-0.035 0 0" rpy="0 0 0" />
        <geometry>
          <box size="0.035 0.035 0.05"/>
        </geometry>
        <material name="DarkGrey" />
      </collision>
    </link>

    <joint name="${name}_joint" type="revolute">
      <parent link="${parent}"/>
        <child link="${name}_link"/>
      <origin xyz="0.0845 0 0.03" rpy="${-90.0 * deg_to_rad} 0 0" />
      <axis xyz="0 0 1" />
      <limit lower="${-15.0 * deg_to_rad}" upper="${45.0 * deg_to_rad}" effort="3.26" velocity="${head_max_vel}" />
      <dynamics damping="${head_damping}" friction="${head_friction}"/>

      <safety_controller k_position="20"
                         k_velocity="20"
                         soft_lower_limit="${-15.0 * deg_to_rad + head_eps}"
                         soft_upper_limit="${ 20.0 * deg_to_rad}" />
    </joint>

  </xacro:macro>

  <xacro:macro name="head" params="name parent">
    <xacro:head_1 name="${name}_1" parent="${parent}" />
    <xacro:head_2 name="${name}_2" parent="${name}_1_link"/>
    <xacro:xtion_pro_live name="xtion" parent="${name}_2">
      <origin xyz="0 -0.03 0" rpy="${90 * deg_to_rad} 0 0" />
      <origin xyz="0 -0.03 0" rpy="0 ${90 * deg_to_rad} 0" />
    </xacro:xtion_pro_live>
  </xacro:macro>

</robot>
