<?xml version="1.0" ?>

<robot xmlns:xacro="http://ros.org/wiki/xacro">

  <!--File includes-->
  <xacro:include filename="$(find tiago_description)/urdf/deg_to_rad.xacro" />

 <!--Constant parameters-->
  <xacro:property name="torso_max_vel"  value="5.4" />
  <xacro:property name="torso_max_effort"  value="78.0" />
  <xacro:property name="torso_eps"      value="0.02" />

  <xacro:macro name="tiago_torso" params="name parent">
  
  <link name="${name}_fixed_link">
    <inertial>
      <origin rpy="0 0 0" xyz="0.053 0.55187 -0.00188" />
      <mass value="7.19400" />
      <inertia ixx="0.16941095831" ixy="-0.00114443001"   ixz="0.00090167218"
               iyy="0.15113888533" iyz="-0.00744737659"
               izz="0.04165307088" />
    </inertial>

    <visual>
      <origin rpy="0 0 0" xyz="0.0 0.0 0" />
      <geometry>
        <box size="0.10 0.22 0.4"/>
      </geometry>
    </visual>

    <collision>
      <origin rpy="0 0 0" xyz="0.0 0.0 0" />
      <geometry>
        <box size="0.10 0.22 0.4"/>
      </geometry>
    </collision>
  </link>
  
  <joint name="${name}_fixed_joint" type="fixed">
    <origin rpy="0 0 0" xyz="-0.053 0 0.3" />
    <parent link="${parent}_link" />
    <child link="${name}_fixed_link" />
    <axis xyz="0 0 0" />
  </joint>
  
  <link name="${name}_lift_link">
    <inertial>
      <origin rpy="0 0 0" xyz="-0.060142360276412 0.00304133533168627 0.343272867034157" />
      <mass value="10.81628746254819" />
      <inertia ixx="0.0641960264706125" ixy="0.001128617953499" ixz="0.00203364821006436"
               iyy="0.061658561971383" iyz="-3.14401755382909E-05"
               izz="0.0376084656328484" />
    </inertial>

    <visual>
      <origin rpy="0 0 0" xyz="0 0 -0.35" />
       <geometry>
        <box size="0.10 0.22 0.7"/>
      </geometry>
    </visual>

    <collision>
      <origin rpy="0 0 0" xyz="0 0 0" />
       <geometry>
        <box size="0.10 0.22 0.7"/>
      </geometry>
    </collision>
  </link>
  
  <joint name="${name}_lift_joint" type="prismatic">
    <origin rpy="0 0 0" xyz="0.0 0 0.26428" />
    <parent link="${name}_fixed_link" />
    <child link="${name}_lift_link" />
    <axis xyz="0 0 1" />
    <limit effort="450" lower="0.0" upper="0.3556" velocity="0.1" />
    <calibration rising="0.0" />
    <dynamics damping="1000" />
  </joint>
  
 </xacro:macro>

</robot>
